Traceback (most recent call last):
  File "C:\Users\novel\AppData\Local\Programs\Python\Python38\lib\site-packages\urllib3\connectionpool.py", line 699, in urlopen
    httplib_response = self._make_request(
  File "C:\Users\novel\AppData\Local\Programs\Python\Python38\lib\site-packages\urllib3\connectionpool.py", line 382, in _make_request
    self._validate_conn(conn)
  File "C:\Users\novel\AppData\Local\Programs\Python\Python38\lib\site-packages\urllib3\connectionpool.py", line 1010, in _validate_conn
    conn.connect()
  File "C:\Users\novel\AppData\Local\Programs\Python\Python38\lib\site-packages\urllib3\connection.py", line 411, in connect
    self.sock = ssl_wrap_socket(
  File "C:\Users\novel\AppData\Local\Programs\Python\Python38\lib\site-packages\urllib3\util\ssl_.py", line 428, in ssl_wrap_socket
    ssl_sock = _ssl_wrap_socket_impl(
  File "C:\Users\novel\AppData\Local\Programs\Python\Python38\lib\site-packages\urllib3\util\ssl_.py", line 472, in _ssl_wrap_socket_impl
    return ssl_context.wrap_socket(sock, server_hostname=server_hostname)
  File "C:\Users\novel\AppData\Local\Programs\Python\Python38\lib\ssl.py", line 500, in wrap_socket
    return self.sslsocket_class._create(
  File "C:\Users\novel\AppData\Local\Programs\Python\Python38\lib\ssl.py", line 1040, in _create
    self.do_handshake()
  File "C:\Users\novel\AppData\Local\Programs\Python\Python38\lib\ssl.py", line 1309, in do_handshake
    self._sslobj.do_handshake()
TimeoutError: [WinError 10060] A connection attempt failed because the connected party did not properly respond after a period of time, or established connection failed because connected host has failed to respond

During handling of the above exception, another exception occurred:

Traceback (most recent call last):
  File "C:\Users\novel\AppData\Local\Programs\Python\Python38\lib\site-packages\requests\adapters.py", line 439, in send
    resp = conn.urlopen(
  File "C:\Users\novel\AppData\Local\Programs\Python\Python38\lib\site-packages\urllib3\connectionpool.py", line 755, in urlopen
    retries = retries.increment(
  File "C:\Users\novel\AppData\Local\Programs\Python\Python38\lib\site-packages\urllib3\util\retry.py", line 531, in increment
    raise six.reraise(type(error), error, _stacktrace)
  File "C:\Users\novel\AppData\Local\Programs\Python\Python38\lib\site-packages\urllib3\packages\six.py", line 734, in reraise
    raise value.with_traceback(tb)
  File "C:\Users\novel\AppData\Local\Programs\Python\Python38\lib\site-packages\urllib3\connectionpool.py", line 699, in urlopen
    httplib_response = self._make_request(
  File "C:\Users\novel\AppData\Local\Programs\Python\Python38\lib\site-packages\urllib3\connectionpool.py", line 382, in _make_request
    self._validate_conn(conn)
  File "C:\Users\novel\AppData\Local\Programs\Python\Python38\lib\site-packages\urllib3\connectionpool.py", line 1010, in _validate_conn
    conn.connect()
  File "C:\Users\novel\AppData\Local\Programs\Python\Python38\lib\site-packages\urllib3\connection.py", line 411, in connect
    self.sock = ssl_wrap_socket(
  File "C:\Users\novel\AppData\Local\Programs\Python\Python38\lib\site-packages\urllib3\util\ssl_.py", line 428, in ssl_wrap_socket
    ssl_sock = _ssl_wrap_socket_impl(
  File "C:\Users\novel\AppData\Local\Programs\Python\Python38\lib\site-packages\urllib3\util\ssl_.py", line 472, in _ssl_wrap_socket_impl
    return ssl_context.wrap_socket(sock, server_hostname=server_hostname)
  File "C:\Users\novel\AppData\Local\Programs\Python\Python38\lib\ssl.py", line 500, in wrap_socket
    return self.sslsocket_class._create(
  File "C:\Users\novel\AppData\Local\Programs\Python\Python38\lib\ssl.py", line 1040, in _create
    self.do_handshake()
  File "C:\Users\novel\AppData\Local\Programs\Python\Python38\lib\ssl.py", line 1309, in do_handshake
    self._sslobj.do_handshake()
urllib3.exceptions.ProtocolError: ('Connection aborted.', TimeoutError(10060, 'A connection attempt failed because the connected party did not properly respond after a period of time, or established connection failed because connected host has failed to respond', None, 10060, None))

During handling of the above exception, another exception occurred:

Traceback (most recent call last):
  File "02_acquire_app_info.py", line 175, in <module>
    app_details, app_reviews = retrieve_info(appid)
  File "02_acquire_app_info.py", line 19, in retrieve_info
    app_details = requests.get('http://store.steampowered.com/api/appdetails?appids=' + str(appid)).text
  File "C:\Users\novel\AppData\Local\Programs\Python\Python38\lib\site-packages\requests\api.py", line 76, in get
    return request('get', url, params=params, **kwargs)
  File "C:\Users\novel\AppData\Local\Programs\Python\Python38\lib\site-packages\requests\api.py", line 61, in request
    return session.request(method=method, url=url, **kwargs)
  File "C:\Users\novel\AppData\Local\Programs\Python\Python38\lib\site-packages\requests\sessions.py", line 542, in request
    resp = self.send(prep, **send_kwargs)
  File "C:\Users\novel\AppData\Local\Programs\Python\Python38\lib\site-packages\requests\sessions.py", line 677, in send
    history = [resp for resp in gen]
  File "C:\Users\novel\AppData\Local\Programs\Python\Python38\lib\site-packages\requests\sessions.py", line 677, in <listcomp>
    history = [resp for resp in gen]
  File "C:\Users\novel\AppData\Local\Programs\Python\Python38\lib\site-packages\requests\sessions.py", line 237, in resolve_redirects
    resp = self.send(
  File "C:\Users\novel\AppData\Local\Programs\Python\Python38\lib\site-packages\requests\sessions.py", line 655, in send
    r = adapter.send(request, **kwargs)
  File "C:\Users\novel\AppData\Local\Programs\Python\Python38\lib\site-packages\requests\adapters.py", line 498, in send
    raise ConnectionError(err, request=request)
requests.exceptions.ConnectionError: ('Connection aborted.', TimeoutError(10060, 'A connection attempt failed because the connected party did not properly respond after a period of time, or established connection failed because connected host has failed to respond', None, 10060, None))
